Workbook

Sheet DM_công đoạn
A1: MÃ CÔNG ĐOẠN | B1: TÊN CÔNG ĐOẠN | C1: TÊN CÔNG ĐOẠN LỚN | E1: MÃ CÔNG ĐOẠN | F1: TÊN CÔNG ĐOẠN | H1: MÃ CÔNG ĐOẠN | I1: MÃ CÔNG ĐOẠN LỚN
E2: MaCongDoan | F2: TenCongDoan | H2: MaCongDoan | I2: MaCongDoanLon
A3: CD001 | B3: BẮN DÂY ĐAI | C3: LẮP RÁP ĐÓNG GÓI | E3: CD001 | F3: BẮN DÂY ĐAI | H3: CD001 | I3: BP001
A4: CD002 | B4: BẮN ỐC CẤY | C4: LẮP RÁP ĐÓNG GÓI | E4: CD002 | F4: BẮN ỐC CẤY | H4: CD002 | I4: BP001
A5: CD003 | B5: BẮN ỐC VÍT | C5: LẮP RÁP ĐÓNG GÓI | E5: CD003 | F5: BẮN ỐC VÍT | H5: CD003 | I5: BP001
A6: CD004 | B6: BẮN VẢI ĐEN | C6: LẮP RÁP ĐÓNG GÓI | E6: CD004 | F6: BẮN VẢI ĐEN | H6: CD004 | I6: BP001
A7: CD005 | B7: BAO GÓI | C7: SOFA | E7: CD005 | F7: BAO GÓI | H7: CD005 | I7: BP002
A8: CD006 | B8: BỌC NỆM | C8: SOFA | E8: CD006 | F8: BỌC NỆM | H8: CD006 | I8: BP002
A9: CD007 | B9: BỌC VÀ BAO GÓI | C9: SOFA | E9: CD007 | F9: BỌC VÀ BAO GÓI | H9: CD007 | I9: BP002
A10: CD008 | B10: BỌC VẢI | C10: SOFA | E10: CD008 | F10: BỌC VẢI | H10: CD008 | I10: BP002
A11: CD009 | B11: BỌC VẢI VÀ BAO GÓI | C11: SOFA | E11: CD009 | F11: BỌC VẢI VÀ BAO GÓI | H11: CD009 | I11: BP002
A12: CD010 | B12: CẮT | C12: GIA CÔNG NEWLD | E12: CD010 | F12: CẮT | H12: CD010 | I12: BP003
A13: CD011 | B13: CẮT ĐỘ | C13: GIA CÔNG NEWLD | E13: CD011 | F13: CẮT ĐỘ | H13: CD011 | I13: BP003
A14: CD012 | B14: CẮT FINGER | C14: GIA CÔNG NEWLD | E14: CD012 | F14: CẮT FINGER | H14: CD012 | I14: BP003
... A83: CD083 | B83: CNC 5 TRỤC | C83: GIA CÔNG NEWLD | E83: CD083 | F83: CNC 5 TRỤC | H83: CD085 | I83: BP008
A84: CD085 | B84: UV | C84: SƠN | E84: CD085 | F84: UV
A85: CD089 | B85: KIỂM TRA | C85: QC | E85: CD089 | F85: KIỂM TRA

Sheet DM_nguồn lực
A1: Mã nguồn lực | B1: Tên nguồn lực | C1: Số nhân sự phân bổ mỗi máy | D1: Thời gian thiết lập
A2: MaNguonLuc | B2: TenNguonLuc | C2: NhanSuPhanBo | D2: ThoiGianThietLap
A3: M000 | B3: Nhân công | C3: 0 | D3: 0
A4: M001 | B4: CNC 3 | C4: 1 | D4: 60
A5: M002 | B5: CNC CẮT 5 | C5: 1 | D5: 2
A6: M003 | B6: CẮT HAI ĐẦU 19 | C6: 1 | D6: 15
A7: M004 | B7: CẮT HAI ĐẦU 30 | C7: 1 | D7: 15
A8: M005 | B8: CẮT TRƯỢT | C8: 1 | D8: 15
A9: M006 | B9: CẮT HAI ĐẦU 32 | C9: 1 | D9: 15
A10: M007 | B10: NHÁM THÙNG 1 | C10: 1 | D10: 5
A11: M008 | B11: NHÁM THÙNG 2 | C11: 1 | D11: 5
A12: M009 | B12: LỌNG 24 | C12: 1 | D12: 1
A13: M010 | B13: LỌNG 25 | C13: 1 | D13: 1
A14: M011 | B14: CNC 1 | C14: =VLOOKUP(B14,'[1]Dữ liệu máy móc'!$E$3:$F$12089,2,FALSE) -> 1 | D14: 30
A15: M012 | B15: CNC 3 | C15: 1 | D15: 60
A16: M013 | B16: CNC 2 | C16: 1 | D16: 30
A17: M014 | B17: CNC KHOAN 6 | C17: =VLOOKUP(B17,'[1]Dữ liệu máy móc'!$E$3:$F$12089,2,FALSE) -> 1 | D17: 20
A18: M015 | B18: CNC KHOAN 7 | C18: 1 | D18: 10
A19: M016 | B19: KHOAN TAY 22,23 | C19: 1 | D19: 10
A20: M017 | B20: KHOAN NGANG 20 | C20: 1 | D20: 40
A21: M018 | B21: CNC TIỆN 4 | C21: =VLOOKUP(B21,'[1]Dữ liệu máy móc'!$E$3:$F$12089,2,FALSE) -> 1 | D21: 15
A22: M019 | B22: KHOAN 3 CHIỀU 21 | C22: 1 | D22: 20
A23: M020 | B23: RÁP KHUNG 28 | C23: =VLOOKUP(B23,'[1]Dữ liệu máy móc'!$E$3:$F$12089,2,FALSE) -> 1 | D23: 15
A24: M021 | B24: ROTO 17 | C24: =VLOOKUP(B24,'[1]Dữ liệu máy móc'!$E$3:$F$12089,2,FALSE) -> 1 | D24: 10
A25: M022 | B25: ROTO 33 | C25: 1 | D25: 10
A26: M023 | B26: TUBI 16 | C26: =VLOOKUP(B26,'[1]Dữ liệu máy móc'!$E$3:$F$12089,2,FALSE) -> 1 | D26: 20
A27: M024 | B27: TUBI 18 | C27: 1 | D27: 20
A28: M025 | B28: CNC 5 TRỤC 35 | C28: =VLOOKUP(B28,'[1]Dữ liệu máy móc'!$E$3:$F$12089,2,FALSE) -> 1 | D28: 90
A29: M026 | B29: ĐÁNH MỘNG 9 | C29: =VLOOKUP(B29,'[1]Dữ liệu máy móc'!$E$3:$F$12089,2,FALSE) -> 1 | D29: 20
A30: M027 | B30: ÉP CẢO 27 | C30: =VLOOKUP(B30,'[1]Dữ liệu máy móc'!$E$3:$F$12089,2,FALSE) -> 1 | D30: 5
A31: M028 | B31: ÉP CAO TẦN 10 | C31: =VLOOKUP(B31,'[1]Dữ liệu máy móc'!$E$3:$F$12089,2,FALSE) -> 2 | D31: 15
A32: M029 | B32: ÉP CẢO TAY | C32: 1 | D32: 5
A33: M030 | B33: LẠNG VENEER | C33: 1 | D33: 5
A34: M031 | B34: CẮT FINGER 39 | C34: 1 | D34: 20
A35: M032 | B35: GHÉP FINGER 40 | C35: 1 | D35: 5

Sheet DM_nguồn lực_công đoạn
A1: MÃ | B1: TÊN CÔNG ĐOẠN | C1: MÁY MÓC THỨ 1 | D1: MÁY MÓC THỨ 2 | E1: MÁY MÓC THỨ 3 | F1: MÁY MÓC THỨ 4 | G1: SỐ LƯỢNG MÁY GỐC | J1: MaCongDoan | K1: MaNguonLuc
A2: CD001 | B2: BẮN DÂY ĐAI | C2: M000 | J2: CD001 | K2: M000
A3: CD002 | B3: BẮN ỐC CẤY | C3: M000 | J3: CD002 | K3: M000
A4: CD003 | B4: BẮN ỐC VÍT | C4: M000 | J4: CD003 | K4: M000
A5: CD004 | B5: BẮN VẢI ĐEN | C5: M000 | J5: CD004 | K5: M000
A6: CD005 | B6: BAO GÓI | C6: M000 | J6: CD005 | K6: M000
A7: CD006 | B7: BỌC NỆM | C7: M000 | J7: CD006 | K7: M000
A8: CD007 | B8: BỌC VÀ BAO GÓI | C8: M000 | J8: CD007 | K8: M000
A9: CD008 | B9: BỌC VẢI | C9: M000 | J9: CD008 | K9: M000
A10: CD009 | B10: BỌC VẢI VÀ BAO GÓI | C10: M000 | J10: CD009 | K10: M000
A11: CD010 | B11: CẮT | C11: M002 | G11: 1 | J11: CD010 | K11: M002
A12: CD011 | B12: CẮT ĐỘ | C12: M003 | D12: M004 | E12: M005 | F12: M006 | G12: 4 | J12: CD011 | K12: M003
A13: CD012 | B13: CẮT FINGER | C13: M003 | G13: 1 | J13: CD012 | K13: M003
A14: CD013 | B14: CẮT HAI ĐẦU | C14: M003 | D14: M004 | E14: M005 | F14: M006 | G14: 4 | J14: CD013 | K14: M003
A15: CD014 | B15: CẮT LẦN 1 | C15: M003 | D15: M004 | E15: M005 | F15: M006 | G15: 4 | J15: CD014 | K15: M003
A16: CD015 | B16: CẮT LẦN 2 | C16: M003 | D16: M004 | E16: M005 | F16: M006 | G16: 4 | J16: CD015 | K16: M003
A17: CD016 | B17: CẮT LAZER | C17: M000 | J17: CD016 | K17: M000
A18: CD017 | B18: CẮT MÚT | C18: M000 | J18: CD017 | K18: M000
A19: CD018 | B19: CẮT NGÀM | C19: M003 | D19: M004 | E19: M005 | F19: M006 | G19: 4 | J19: CD018 | K19: M003
A20: CD019 | B20: CẮT TINH | C20: M003 | D20: M004 | E20: M005 | F20: M006 | G20: 4 | J20: CD019 | K20: M003
A21: CD020 | B21: CẮT VÀ DÁN LAMINAT | C21: M000 | J21: CD020 | K21: M000
A22: CD021 | B22: CẮT VÀ DÁN MÚT | C22: M000 | J22: CD021 | K22: M000
A23: CD022 | B23: CẮT VÀ ĐỊNH HÌNH | C23: M000 | J23: CD022 | K23: M000
A24: CD023 | B24: CẮT VÀ MAY | C24: M000 | J24: CD023 | K24: M000
A25: CD024 | B25: CHÀ ĐỘ | C25: M000 | J25: CD024 | K25: M000
A26: CD025 | B26: CHÀ NHÁM | C26: M000 | J26: CD025 | K26: M000
A27: CD026 | B27: CHÀ NHÁM 1 | C27: M000 | J27: CD026 | K27: M000
A28: CD027 | B28: CHÀ NHÁM 2 | C28: M000 | J28: CD027 | K28: M000
A29: CD028 | B29: CHÀ NHÁM THÙNG | C29: M007 | D29: M008 | G29: 2 | J29: CD028 | K29: M007
A30: CD058 | B30: LÍP BÀO CẮT | C30: M000 | J30: CD058 | K30: M000
A31: CD059 | B31: LỌNG | C31: M009 | D31: M010 | G31: 2 | J31: CD059 | K31: M009
A32: CD060 | B32: LỰA LIỆU | C32: M000 | J32: CD060 | K32: M000
A33: CD029 | B33: CNC | C33: M011 | D33: M012 | E33: M013 | G33: 3 | J33: CD029 | K33: M011
A34: CD030 | B34: CNC 1 | C34: M011 | G34: 1 | J34: CD030 | K34: M011
A35: CD031 | B35: CNC 3 | C35: M000 | J35: CD031 | K35: M000
A36: CD048 | B36: KHOAN | C36: M014 | D36: M015 | E36: M016 | F36: M017 | G36: 4 | J36: CD048 | K36: M014
A37: CD049 | B37: KHOAN LẦN 1 | C37: M014 | D37: M015 | E37: M016 | F37: M017 | G37: 4 | J37: CD049 | K37: M014
A38: CD050 | B38: KHOAN LẦN 2 | C38: M014 | D38: M015 | E38: M016 | F38: M017 | G38: 4 | J38: CD050 | K38: M014
A39: CD051 | B39: KHOAN LẦN 3 | C39: M014 | D39: M015 | E39: M016 | F39: M017 | G39: 4 | J39: CD051 | K39: M014
A40: CD052 | B40: KHOAN LẦN 4 | C40: M014 | D40: M015 | E40: M016 | F40: M017 | G40: 4 | J40: CD052 | K40: M014
...

Sheet DM_định mức sản phẩm
A1: [DinhMucID] | B1: LoaiSanPham | C1: MaSanPham | D1: TenSanPham | E1: [DinhLuong] | F1: [DinhMucThoiGian] | G1: [MaCongDoan]
A2: 36 | B2: TP | C2: 4550182598490 | D2: Table 1 - wnl | E2: 1 | F2: 3.3333333 | G2: CD038
A3: 37 | B3: BTP | C3: BTP1830000000 | D3: Mặt bàn WNL (1500*650*20) - Bàn 1 | E3: 1 | F3: 1.5 | G3: CD003
A4: 38 | B4: BTP | C4: BTP1830000000C2 | D4: Mặt bàn WNL (1500*650*20) - Bàn 1 | E4: 1 | F4: 3 | G4: CD029
A5: 39 | B5: BTP | C5: BTP1830000000N1 | D5: Mặt bàn WNL (1500*650*20) - Bàn 1 | E5: 1 | F5: 21.4 | G5: CD026
A6: 40 | B6: BTP | C6: BTP1830000000SL | D6: Mặt bàn WNL (1500*650*20) - Bàn 1 | E6: 1 | F6: 10.42 | G6: CD075
A7: 41 | B7: BTP | C7: BTP1830000000N2 | D7: Mặt bàn WNL (1500*650*20) - Bàn 1 | E7: 1 | F7: 5.7 | G7: CD027
A8: 42 | B8: BTP | C8: BTP1830000000PU | D8: Mặt bàn WNL (1500*650*20) - Bàn 1 | E8: 1 | F8: 3.68 | G8: CD065
A9: 43 | B9: BTP | C9: BTP1850000000 | D9: Chân WNL (580*550*30) - Bàn 1 + Bàn 2 | E9: 2 | F9: 0.75 | G9: CD003
A10: 44 | B10: BTP | C10: BTP1850000000CC | D10: Chân WNL (580*550*30) - Bàn 1 | E10: 2 | F10: 0.73333333 | G10: CD010
A11: 45 | B11: BTP | C11: BTP1850000000C3 | D11: Chân WNL (580*550*30) - Bàn 1 | E11: 2 | F11: 5.8 | G11: CD029
A12: 46 | B12: BTP | C12: BTP1850000000KC | D12: Chân WNL (580*550*30) - Bàn 1 | E12: 2 | F12: 0.5 | G12: CD048
A13: 47 | B13: BTP | C13: BTP1850000000N1 | D13: Chân WNL (580*550*30) - Bàn 1 | E13: 2 | F13: 12.8 | G13: CD026
... A219: 253 | B219: BTP | C219: BTP2270000001 | D219: KHUNG BEN 2 WALNUT CÓ LÓT MẶT | E219: 1 | F219: 6.88 | G219: CD056

Sheet DM_TP_BTP
A1: [TP_DinhMucID] | B1: [BTP_DinhMucID] | C1: [ThuTuSX]
A2: 36 | B2: 37 | C2: 6
A3: 36 | B3: 38 | C3: 1
A4: 36 | B4: 39 | C4: 2
A5: 36 | B5: 40 | C5: 3
A6: 36 | B6: 41 | C6: 4
A7: 36 | B7: 42 | C7: 5
A8: 36 | B8: 43 | C8: 14
A9: 36 | B9: 44 | C9: 7
A10: 36 | B10: 45 | C10: 8
A11: 36 | B11: 46 | C11: 9
A12: 36 | B12: 47 | C12: 10
A13: 36 | B13: 48 | C13: 11
A14: 36 | B14: 49 | C14: 12
A15: 36 | B15: 50 | C15: 13
A16: 36 | B16: 51 | C16: 21
A17: 36 | B17: 52 | C17: 15
A18: 36 | B18: 53 | C18: 16
A19: 36 | B19: 54 | C19: 17
A20: 36 | B20: 55 | C20: 18
A21: 36 | B21: 56 | C21: 19
A22: 36 | B22: 57 | C22: 20
A23: 36 | B23: 58 | C23: 27
A24: 36 | B24: 59 | C24: 22
A25: 36 | B25: 60 | C25: 23
A26: 36 | B26: 61 | C26: 24
A27: 36 | B27: 62 | C27: 25
A28: 36 | B28: 63 | C28: 26
... A34: 36 | B34: 69 | C34: 32
A35: 70 | B35: 71 | C35: 6
A36: 70 | B36: 72 | C36: 1
A37: 70 | B37: 73 | C37: 2
A38: 70 | B38: 74 | C38: 3
A39: 70 | B39: 75 | C39: 4
A40: 70 | B40: 76 | C40: 5
A41: 70 | B41: 43 | C41: 14
A42: 70 | B42: 44 | C42: 7
A43: 70 | B43: 45 | C43: 8
A44: 70 | B44: 46 | C44: 9
A45: 70 | B45: 47 | C45: 10
...

Sheet ĐƠN HÀNG SẢN XUẤT
A1: STT | B1: Số chứng từ | C1: Khách hàng | D1: Ngày giao hàng | E1: Mã hàng | F1: Số lượng đặt hàng | G1: Ngày hoàn thành
A2: 1 | B2: DHSX/12/2025/011 | C2: NITORI | D2: 46032 | E2: 4550182598490 | F2: 45 | G2: 46031
E3: 4550182598506 | F3: 73 | G3: 46031
E4: 2023024Z2800 | F4: 55 | G4: 46031
E5: 4550182598513 | F5: 10 | G5: 46031
A6: 2 | B6: DHSX/12/2025/012 | C6: MISAWA | D6: 46037 | E6: 4550182598476 | F6: 89 | G6: 46036
E7: 4550182598520 | F7: 76 | G7: 46036
E8: 2023024Z2800 | F8: 77 | G8: 46036
E9: 2023024Z2900 | F9: 100 | G9: 46036
A10: 3 | B10: DHSX/12/2025/013 | C10: OLIVER | D10: 46039 | E10: 4550182598513 | F10: 87 | G10: 46038
E11: 4550182598476 | F11: 22 | G11: 46038
E12: 2023024Z2800 | F12: 66 | G12: 46038
E13: 2023024Z2900 | F13: 66 | G13: 46038
E14: 4550182598520 | F14: 34 | G14: 46038
A15: 4 | B15: DHSX/12/2025/014 | C15: TOKYO | D15: 46044 | E15: 4550182598490 | F15: 69 | G15: 46043
E16: 4550182598551 | F16: 40 | G16: 46043
E17: 4550182598513 | F17: 25 | G17: 46043
E18: 2023024Z2900 | F18: 25 | G18: 46043
E19: 2023024Z2800 | F19: 88 | G19: 46043
E20: 4550182598476 | F20: 13 | G20: 46043
A21: 5 | B21: DHSX/12/2025/015 | C21: RISE | D21: 46046 | E21: 4550182598520 | F21: 16 | G21: 46045
E22: 4550182598551 | F22: 45 | G22: 46045
E23: 2023024Z2900 | F23: 78 | G23: 46045
E24: 2023024Z2800 | F24: 99 | G24: 46045
E25: 4550182598513 | F25: 120 | G25: 46045
A26: 6 | B26: DHSX/12/2025/016 | C26: SUSHIRO | D26: 46047 | E26: 4550182598490 | F26: 124 | G26: 46046
E27: 4550182598476 | F27: 54 | G27: 46046
E28: 4550182598551 | F28: 50 | G28: 46046
E29: 4550182598520 | F29: 67 | G29: 46046
A30: 7 | B30: DHSX/12/2025/017 | C30: TOKYO INTER | D30: 46051 | E30: 4550182598506 | F30: 133 | G30: 46050
E31: 4550182598513 | F31: 124 | G31: 46050
E32: 2023024Z2900 | F32: 124 | G32: 46050
E33: 4550182598476 | F33: 90 | G33: 46050
E34: 4550182598551 | F34: 43 | G34: 46050

Sheet ĐỊNH MỨC SẢN PHẨM
A1: STT | B1: Mã TP | C1: Mã nhóm BTP | D1: Mã BTP | E1: MÃ CÔNG ĐOẠN | F1: TÊN CÔNG ĐOẠN | G1: Định lượng | H1: Định mức thời gian | I1: NGUỒN LỰC 1 | J1: Thứ tự SX | K1: NGUỒN LỰC 2 | L1: NGUỒN LỰC 3 | M1: NGUỒN LỰC 4
A2: 1 | B2: 4550182598490 | D2: 4550182598490 | E2: CD038 | F2: ĐÓNG GÓI | G2: 1 | H2: 3.3333333 | I2: M000
B3: 6 | C3: BTP1830000000 | D3: BTP1830000000 | E3: CD003 | F3: BẮN ỐC VÍT | G3: 1 | H3: 1.5 | I3: M000 | J3: 6
B4: 1 | D4: BTP1830000000C2 | E4: CD029 | F4: CNC | G4: 1 | H4: 3 | I4: M011 | J4: 1 | K4: M012 | L4: M013
B5: 2 | D5: BTP1830000000N1 | E5: CD026 | F5: CHÀ NHÁM 1 | G5: 1 | H5: 21.4 | I5: M000 | J5: 2
B6: 3 | D6: BTP1830000000SL | E6: CD075 | F6: SƠN LÓT | G6: 1 | H6: 10.42 | I6: M000 | J6: 3
B7: 4 | D7: BTP1830000000N2 | E7: CD027 | F7: CHÀ NHÁM 2 | G7: 1 | H7: 5.7 | I7: M000 | J7: 4
B8: 5 | D8: BTP1830000000PU | E8: CD065 | F8: PU | G8: 1 | H8: 3.68 | I8: M000 | J8: 5
B9: 8 | C9: BTP1850000000 | D9: BTP1850000000 | E9: CD003 | F9: BẮN ỐC VÍT | G9: 2 | H9: 0.75 | I9: M000 | J9: 14
B10: 1 | D10: BTP1850000000CC | E10: CD010 | F10: CẮT | G10: 2 | H10: 0.73333333 | I10: M002 | J10: 7
B11: 2 | D11: BTP1850000000C3 | E11: CD029 | F11: CNC | G11: 2 | H11: 5.8 | I11: M011 | J11: 8 | K11: M012 | L11: M013
B12: 3 | D12: BTP1850000000KC | E12: CD048 | F12: KHOAN | G12: 2 | H12: 0.5 | I12: M014 | J12: 9 | K12: M015 | L12: M016 | M12: M017
B13: 4 | D13: BTP1850000000N1 | E13: CD026 | F13: CHÀ NHÁM 1 | G13: 2 | H13: 12.8 | I13: M000 | J13: 10
B14: 5 | D14: BTP1850000000SL | E14: CD075 | F14: SƠN LÓT | G14: 2 | H14: 0.8 | I14: M000 | J14: 11
B15: 6 | D15: BTP1850000000N2 | E15: CD027 | F15: CHÀ NHÁM 2 | G15: 2 | H15: 5 | I15: M000 | J15: 12
B16: 7 | D16: BTP1850000000SB | E16: CD074 | F16: SƠN BÓNG | G16: 2 | H16: 0.8 | I16: M000 | J16: 13
B17: 7 | C17: BTP1870000000 | D17: BTP1870000000 | E17: CD074 | F17: SƠN BÓNG | G17: 1 | H17: 0.9 | I17: M000 | J17: 21
B18: 1 | D18: BTP1870000000CC | E18: CD010 | F18: CẮT | G18: 1 | H18: 0.45 | I18: M002 | J18: 15
B19: 2 | D19: BTP1870000000TB | E19: CD077 | F19: TUBI | G19: 1 | H19: 0.16666667 | I19: M023 | J19: 16 | K19: M024
B20: 3 | D20: BTP1870000000KC | E20: CD048 | F20: KHOAN | G20: 1 | H20: 3.4166667 | I20: M014 | J20: 17 | K20: M015 | L20: M016 | M20: M017
B21: 4 | D21: BTP1870000000N1 | E21: CD026 | F21: CHÀ NHÁM 1 | G21: 1 | H21: 15.73 | I21: M000 | J21: 18
B22: 5 | D22: BTP1870000000SL | E22: CD075 | F22: SƠN LÓT | G22: 1 | H22: 0.24 | I22: M000 | J22: 19
B23: 6 | D23: BTP1870000000N2 | E23: CD027 | F23: CHÀ NHÁM 2 | G23: 1 | H23: 2.85 | I23: M000 | J23: 20
C24: BTP1890000000 | D24: BTP1890000000 | E24: CD074 | F24: SƠN BÓNG | G24: 1 | H24: 0.9 | I24: M000 | J24: 27
D25: BTP1890000000CC | E25: CD010 | F25: CẮT | G25: 1 | H25: 0.37037037 | I25: M002 | J25: 22
D26: BTP1890000000KC | E26: CD048 | F26: KHOAN | G26: 1 | H26: 3.5 | I26: M014 | J26: 23 | K26: M015 | L26: M016 | M26: M017
D27: BTP1890000000N1 | E27: CD026 | F27: CHÀ NHÁM 1 | G27: 1 | H27: 15.12 | I27: M000 | J27: 24
D28: BTP1890000000SL | E28: CD075 | F28: SƠN LÓT | G28: 1 | H28: 0.74 | I28: M000 | J28: 25
D29: BTP1890000000N2 | E29: CD027 | F29: CHÀ NHÁM 2 | G29: 1 | H29: 2.4 | I29: M000 | J29: 26
C30: BTP1910000000 | D30: BTP1910000000 | E30: CD003 | F30: BẮN ỐC VÍT | G30: 1 | H30: 0.75 | I30: M000 | J30: 33
D31: BTP1910000000C2 | E31: CD029 | F31: CNC | G31: 1 | H31: 1.5 | I31: M011 | J31: 28 | K31: M012 | L31: M013
D32: BTP1910000000N1 | E32: CD026 | F32: CHÀ NHÁM 1 | G32: 1 | H32: 6 | I32: M000 | J32: 29
D33: BTP1910000000N2 | E33: CD027 | F33: CHÀ NHÁM 2 | G33: 1 | H33: 6.25 | I33: M000 | J33: 30
D34: BTP1910000000SB | E34: CD074 | F34: SƠN BÓNG | G34: 1 | H34: 1.2 | I34: M000 | J34: 31
D35: BTP1910000000SL | E35: CD075 | F35: SƠN LÓT | G35: 1 | H35: 0.28 | I35: M000 | J35: 32
A36: 2 | B36: 4550182598506 | D36: 4550182598506 | E36: CD038 | F36: ĐÓNG GÓI | G36: 1 | H36: 3.3333333 | I36: M000
C37: BTP1930000000 | D37: BTP1930000000 | E37: CD003 | F37: BẮN ỐC VÍT | G37: 1 | H37: 1.5 | I37: M000 | J37: 6
D38: BTP1930000000N1 | E38: CD026 | F38: CHÀ NHÁM 1 | G38: 1 | H38: 21.4 | I38: M000 | J38: 1
D39: BTP1930000000SL | E39: CD075 | F39: SƠN LÓT | G39: 1 | H39: 10 | I39: M000 | J39: 2
D40: BTP1930000000N2 | E40: CD027 | F40: CHÀ NHÁM 2 | G40: 1 | H40: 5.7 | I40: M000 | J40: 3
...

Sheet Kế hoạch sản xuất
V1: 22/01
A2: STT | B2: Số chứng từ | C2: Mã hàng | D2: Tên hàng | E2: Số lượng đặt hàng | F2: Ngày giao hàng | G2: Mã bán thành phẩm | H2: Tên bán thành phẩm | I2: Mã công đoạn lớn | J2: Công đoạn lớn | K2: Mã công đoạn | L2: Tên công đoạn | M2: Định lượng | N2: Thời gian định mức | O2: Nguồn lực | P2: Số lượng nguồn lực | Q2: Số lượng nguồn lực phân bổ máy | R2: Thời gian thiết lập máy | S2: Thứ tự sản xuất | T2: Tổng số lượng sản xuất | U2: Tổng thời gian sản xuất | V2: % Nguồn lực khả dụng | W2: % Thời gian khả dụng | X2: Sản lượng sản xuất thực tế
A3: 1 | B3: DHSX/12/2025/011 | C3: 4550182598490 | D3: Table 1 - wnl | E3: 45 | F3: 46143 | G3: BTP1830000000 | H3: =VLOOKUP(G3, 'DM_định mức sản phẩm'!C:D, 2, 0) -> Mặt bàn WNL (1500*650*20) - Bàn 1 | I3: =_xlfn.XLOOKUP(K3, 'DM_công đoạn'!$H$3:$H$1000, 'DM_công đoạn'!$I$3:$I$1000) -> BP001 | J3: =_xlfn.XLOOKUP(L3, 'DM_công đoạn'!$B$3:$B$1000, 'DM_công đoạn'!$C$3:$C$1000) -> LẮP RÁP ĐÓNG GÓI | K3: CD003 | L3: BẮN ỐC VÍT | M3: 1 | N3: 1.5 | O3: M000 | P3: 8 | Q3: 0 | R3: 0 | S3: 6 | T3: =M3*45 -> 45 | U3: =T3*N3/60 -> 1.125
G4: BTP1830000000C2 | H4: =VLOOKUP(G4, 'DM_định mức sản phẩm'!C:D, 2, 0) -> Mặt bàn WNL (1500*650*20) - Bàn 1 | I4: =_xlfn.XLOOKUP(K4, 'DM_công đoạn'!$H$3:$H$1000, 'DM_công đoạn'!$I$3:$I$1000) -> BP003 | J4: =_xlfn.XLOOKUP(L4, 'DM_công đoạn'!$B$3:$B$1000, 'DM_công đoạn'!$C$3:$C$1000) -> GIA CÔNG NEWLD | K4: CD029 | L4: CNC | M4: 1 | N4: 3 | O4: M011, M012, M013 | P4: 3 | Q4: 1 | R4: 30 | S4: 1 | T4: =M4*45 -> 45 | U4: =T4*N4/60 -> 2.25
G5: BTP1830000000N1 | H5: =VLOOKUP(G5, 'DM_định mức sản phẩm'!C:D, 2, 0) -> Mặt bàn WNL (1500*650*20) - Bàn 1 | I5: =_xlfn.XLOOKUP(K5, 'DM_công đoạn'!$H$3:$H$1000, 'DM_công đoạn'!$I$3:$I$1000) -> BP007 | J5: =_xlfn.XLOOKUP(L5, 'DM_công đoạn'!$B$3:$B$1000, 'DM_công đoạn'!$C$3:$C$1000) -> CHÀ NHÁM | K5: CD026 | L5: CHÀ NHÁM 1 | M5: 1 | N5: 21.4 | O5: M000 | P5: 24 | Q5: 0 | R5: 0 | S5: 2 | T5: =M5*45 -> 45 | U5: =T5*N5/60 -> 16.05
G6: BTP1830000000SL | H6: =VLOOKUP(G6, 'DM_định mức sản phẩm'!C:D, 2, 0) -> Mặt bàn WNL (1500*650*20) - Bàn 1 | I6: =_xlfn.XLOOKUP(K6, 'DM_công đoạn'!$H$3:$H$1000, 'DM_công đoạn'!$I$3:$I$1000) -> BP008 | J6: =_xlfn.XLOOKUP(L6, 'DM_công đoạn'!$B$3:$B$1000, 'DM_công đoạn'!$C$3:$C$1000) -> SƠN | K6: CD075 | L6: SƠN LÓT | M6: 1 | N6: 10.42 | O6: M000 | P6: 12 | Q6: 0 | R6: 0 | S6: 3 | T6: =M6*45 -> 45 | U6: =T6*N6/60 -> 7.815
G7: BTP1830000000N2 | H7: =VLOOKUP(G7, 'DM_định mức sản phẩm'!C:D, 2, 0) -> Mặt bàn WNL (1500*650*20) - Bàn 1 | I7: =_xlfn.XLOOKUP(K7, 'DM_công đoạn'!$H$3:$H$1000, 'DM_công đoạn'!$I$3:$I$1000) -> BP007 | J7: =_xlfn.XLOOKUP(L7, 'DM_công đoạn'!$B$3:$B$1000, 'DM_công đoạn'!$C$3:$C$1000) -> CHÀ NHÁM | K7: CD027 | L7: CHÀ NHÁM 2 | M7: 1 | N7: 5.7 | O7: M000 | P7: 24 | Q7: 0 | R7: 0 | S7: 4 | T7: =M7*45 -> 45 | U7: =T7*N7/60 -> 4.275
G8: BTP1830000000PU | H8: =VLOOKUP(G8, 'DM_định mức sản phẩm'!C:D, 2, 0) -> Mặt bàn WNL (1500*650*20) - Bàn 1 | I8: =_xlfn.XLOOKUP(K8, 'DM_công đoạn'!$H$3:$H$1000, 'DM_công đoạn'!$I$3:$I$1000) -> BP008 | J8: =_xlfn.XLOOKUP(L8, 'DM_công đoạn'!$B$3:$B$1000, 'DM_công đoạn'!$C$3:$C$1000) -> SƠN | K8: CD065 | L8: PU | M8: 1 | N8: 3.68 | O8: M000 | P8: 12 | Q8: 0 | R8: 0 | S8: 5 | T8: =M8*45 -> 45 | U8: =T8*N8/60 -> 2.76
G9: BTP1850000000 | H9: =VLOOKUP(G9, 'DM_định mức sản phẩm'!C:D, 2, 0) -> Chân WNL (580*550*30) - Bàn 1 + Bàn 2 | I9: =_xlfn.XLOOKUP(K9, 'DM_công đoạn'!$H$3:$H$1000, 'DM_công đoạn'!$I$3:$I$1000) -> BP001 | J9: =_xlfn.XLOOKUP(L9, 'DM_công đoạn'!$B$3:$B$1000, 'DM_công đoạn'!$C$3:$C$1000) -> LẮP RÁP ĐÓNG GÓI | K9: CD003 | L9: BẮN ỐC VÍT | M9: 2 | N9: 0.75 | O9: M000 | P9: 8 | Q9: 0 | R9: 0 | S9: 14 | T9: =M9*45 -> 90 | U9: =T9*N9/60 -> 1.125
G10: BTP1850000000CC | H10: =VLOOKUP(G10, 'DM_định mức sản phẩm'!C:D, 2, 0) -> Chân WNL (580*550*30) - Bàn 1 | I10: =_xlfn.XLOOKUP(K10, 'DM_công đoạn'!$H$3:$H$1000, 'DM_công đoạn'!$I$3:$I$1000) -> BP003 | J10: =_xlfn.XLOOKUP(L10, 'DM_công đoạn'!$B$3:$B$1000, 'DM_công đoạn'!$C$3:$C$1000) -> GIA CÔNG NEWLD | K10: CD010 | L10: CẮT | M10: 2 | N10: 0.73333333 | O10: M002 | P10: 1 | Q10: 1 | R10: 2 | S10: 7 | T10: =M10*45 -> 90 | U10: =T10*N10/60 -> 1.1
G11: BTP1850000000C3 | H11: =VLOOKUP(G11, 'DM_định mức sản phẩm'!C:D, 2, 0) -> Chân WNL (580*550*30) - Bàn 1 | I11: =_xlfn.XLOOKUP(K11, 'DM_công đoạn'!$H$3:$H$1000, 'DM_công đoạn'!$I$3:$I$1000) -> BP003 | J11: =_xlfn.XLOOKUP(L11, 'DM_công đoạn'!$B$3:$B$1000, 'DM_công đoạn'!$C$3:$C$1000) -> GIA CÔNG NEWLD | K11: CD029 | L11: CNC | M11: 2 | N11: 5.8 | O11: M011, M012, M013 | P11: 3 | Q11: 1 | R11: 30 | S11: 8 | T11: =M11*45 -> 90 | U11: =T11*N11/60 -> 8.7
G12: BTP1850000000KC | H12: =VLOOKUP(G12, 'DM_định mức sản phẩm'!C:D, 2, 0) -> Chân WNL (580*550*30) - Bàn 1 | I12: =_xlfn.XLOOKUP(K12, 'DM_công đoạn'!$H$3:$H$1000, 'DM_công đoạn'!$I$3:$I$1000) -> BP003 | J12: =_xlfn.XLOOKUP(L12, 'DM_công đoạn'!$B$3:$B$1000, 'DM_công đoạn'!$C$3:$C$1000) -> GIA CÔNG NEWLD | K12: CD048 | L12: KHOAN | M12: 2 | N12: 0.5 | O12: M014, M015, M016, M017 | P12: 4 | Q12: 1 | R12: 20 | S12: 9 | T12: =M12*45 -> 90 | U12: =T12*N12/60 -> 0.75
G13: BTP1850000000N1 | H13: =VLOOKUP(G13, 'DM_định mức sản phẩm'!C:D, 2, 0) -> Chân WNL (580*550*30) - Bàn 1 | I13: =_xlfn.XLOOKUP(K13, 'DM_công đoạn'!$H$3:$H$1000, 'DM_công đoạn'!$I$3:$I$1000) -> BP007 | J13: =_xlfn.XLOOKUP(L13, 'DM_công đoạn'!$B$3:$B$1000, 'DM_công đoạn'!$C$3:$C$1000) -> CHÀ NHÁM | K13: CD026 | L13: CHÀ NHÁM 1 | M13: 2 | N13: 12.8 | O13: M000 | P13: 24 | Q13: 0 | R13: 0 | S13: 10 | T13: =M13*45 -> 90 | U13: =T13*N13/60 -> 19.2
G14: BTP1850000000SL | H14: =VLOOKUP(G14, 'DM_định mức sản phẩm'!C:D, 2, 0) -> Chân WNL (580*550*30) - Bàn 1 | I14: =_xlfn.XLOOKUP(K14, 'DM_công đoạn'!$H$3:$H$1000, 'DM_công đoạn'!$I$3:$I$1000) -> BP008 | J14: =_xlfn.XLOOKUP(L14, 'DM_công đoạn'!$B$3:$B$1000, 'DM_công đoạn'!$C$3:$C$1000) -> SƠN | K14: CD075 | L14: SƠN LÓT | M14: 2 | N14: 0.8 | O14: M000 | P14: 12 | Q14: 0 | R14: 0 | S14: 11 | T14: =M14*45 -> 90 | U14: =T14*N14/60 -> 1.2
G15: BTP1850000000N2 | H15: =VLOOKUP(G15, 'DM_định mức sản phẩm'!C:D, 2, 0) -> Chân WNL (580*550*30) - Bàn 1 | I15: =_xlfn.XLOOKUP(K15, 'DM_công đoạn'!$H$3:$H$1000, 'DM_công đoạn'!$I$3:$I$1000) -> BP007 | J15: =_xlfn.XLOOKUP(L15, 'DM_công đoạn'!$B$3:$B$1000, 'DM_công đoạn'!$C$3:$C$1000) -> CHÀ NHÁM | K15: CD027 | L15: CHÀ NHÁM 2 | M15: 2 | N15: 5 | O15: M000 | P15: 24 | Q15: 0 | R15: 0 | S15: 12 | T15: =M15*45 -> 90 | U15: =T15*N15/60 -> 7.5
... G36: 4550182598490 | H36: =VLOOKUP(G36, 'DM_định mức sản phẩm'!C:D, 2, 0) -> Table 1 - wnl | I36: =_xlfn.XLOOKUP(K36, 'DM_công đoạn'!$H$3:$H$1000, 'DM_công đoạn'!$I$3:$I$1000) -> BP001 | J36: =_xlfn.XLOOKUP(L36, 'DM_công đoạn'!$B$3:$B$1000, 'DM_công đoạn'!$C$3:$C$1000) -> LẮP RÁP ĐÓNG GÓI | K36: CD038 | L36: ĐÓNG GÓI | M36: 1 | N36: 3.3333333 | O36: M000 | P36: 8 | Q36: 0 | R36: 0 | S36: 33 | T36: =M36*45 -> 45 | U36: =T36*N36/60 -> 2.5
C37: 4550182598506 | D37: Table 2 - wnl | E37: 73 | F37: 46143 | G37: BTP1930000000 | H37: =VLOOKUP(G37, 'DM_định mức sản phẩm'!C:D, 2, 0) -> Mặt bàn WNL (1300*650*20) - Bàn 2 | I37: =_xlfn.XLOOKUP(K37, 'DM_công đoạn'!$H$3:$H$1000, 'DM_công đoạn'!$I$3:$I$1000) -> BP001 | J37: =_xlfn.XLOOKUP(L37, 'DM_công đoạn'!$B$3:$B$1000, 'DM_công đoạn'!$C$3:$C$1000) -> LẮP RÁP ĐÓNG GÓI | K37: CD003 | L37: BẮN ỐC VÍT | M37: 1 | N37: 1.5 | O37: M000 | P37: 8 | Q37: 0 | R37: 0 | S37: 6 | T37: =M37*73 -> 73 | U37: =T37*N37/60 -> 1.825
G38: BTP1930000000N1 | H38: =VLOOKUP(G38, 'DM_định mức sản phẩm'!C:D, 2, 0) -> Mặt bàn WNL (1300*650*20) - Bàn 2 | I38: =_xlfn.XLOOKUP(K38, 'DM_công đoạn'!$H$3:$H$1000, 'DM_công đoạn'!$I$3:$I$1000) -> BP007 | J38: =_xlfn.XLOOKUP(L38, 'DM_công đoạn'!$B$3:$B$1000, 'DM_công đoạn'!$C$3:$C$1000) -> CHÀ NHÁM | K38: CD026 | L38: CHÀ NHÁM 1 | M38: 1 | N38: 21.4 | O38: M000 | P38: 24 | Q38: 0 | R38: 0 | S38: 1 | T38: =M38*73 -> 73 | U38: =T38*N38/60 -> 26.036667
G39: BTP1930000000SL | H39: =VLOOKUP(G39, 'DM_định mức sản phẩm'!C:D, 2, 0) -> Mặt bàn WNL (1300*650*20) - Bàn 2 | I39: =_xlfn.XLOOKUP(K39, 'DM_công đoạn'!$H$3:$H$1000, 'DM_công đoạn'!$I$3:$I$1000) -> BP008 | J39: =_xlfn.XLOOKUP(L39, 'DM_công đoạn'!$B$3:$B$1000, 'DM_công đoạn'!$C$3:$C$1000) -> SƠN | K39: CD075 | L39: SƠN LÓT | M39: 1 | N39: 10 | O39: M000 | P39: 12 | Q39: 0 | R39: 0 | S39: 2 | T39: =M39*73 -> 73 | U39: =T39*N39/60 -> 12.166667
G40: BTP1930000000N2 | H40: =VLOOKUP(G40, 'DM_định mức sản phẩm'!C:D, 2, 0) -> Mặt bàn WNL (1300*650*20) - Bàn 2 | I40: =_xlfn.XLOOKUP(K40, 'DM_công đoạn'!$H$3:$H$1000, 'DM_công đoạn'!$I$3:$I$1000) -> BP007 | J40: =_xlfn.XLOOKUP(L40, 'DM_công đoạn'!$B$3:$B$1000, 'DM_công đoạn'!$C$3:$C$1000) -> CHÀ NHÁM | K40: CD027 | L40: CHÀ NHÁM 2 | M40: 1 | N40: 5.7 | O40: M000 | P40: 24 | Q40: 0 | R40: 0 | S40: 3 | T40: =M40*73 -> 73 | U40: =T40*N40/60 -> 6.935
G41: BTP1930000000C2 | H41: =VLOOKUP(G41, 'DM_định mức sản phẩm'!C:D, 2, 0) -> Mặt bàn WNL (1300*650*20) - Bàn 2 | I41: =_xlfn.XLOOKUP(K41, 'DM_công đoạn'!$H$3:$H$1000, 'DM_công đoạn'!$I$3:$I$1000) -> BP003 | J41: =_xlfn.XLOOKUP(L41, 'DM_công đoạn'!$B$3:$B$1000, 'DM_công đoạn'!$C$3:$C$1000) -> GIA CÔNG NEWLD | K41: CD029 | L41: CNC | M41: 1 | N41: 2 | O41: M011, M012, M013 | P41: 3 | Q41: 1 | R41: 30 | S41: 4 | T41: =M41*73 -> 73 | U41: =T41*N41/60 -> 2.4333333
G42: BTP1930000000PU | H42: =VLOOKUP(G42, 'DM_định mức sản phẩm'!C:D, 2, 0) -> Mặt bàn WNL (1300*650*20) - Bàn 2 | I42: =_xlfn.XLOOKUP(K42, 'DM_công đoạn'!$H$3:$H$1000, 'DM_công đoạn'!$I$3:$I$1000) -> BP008 | J42: =_xlfn.XLOOKUP(L42, 'DM_công đoạn'!$B$3:$B$1000, 'DM_công đoạn'!$C$3:$C$1000) -> SƠN | K42: CD065 | L42: PU | M42: 1 | N42: 3.68 | O42: M000 | P42: 12 | Q42: 0 | R42: 0 | S42: 5 | T42: =M42*73 -> 73 | U42: =T42*N42/60 -> 4.4773333
G43: BTP1850000000 | H43: =VLOOKUP(G43, 'DM_định mức sản phẩm'!C:D, 2, 0) -> Chân WNL (580*550*30) - Bàn 1 + Bàn 2 | I43: =_xlfn.XLOOKUP(K43, 'DM_công đoạn'!$H$3:$H$1000, 'DM_công đoạn'!$I$3:$I$1000) -> BP001 | J43: =_xlfn.XLOOKUP(L43, 'DM_công đoạn'!$B$3:$B$1000, 'DM_công đoạn'!$C$3:$C$1000) -> LẮP RÁP ĐÓNG GÓI | K43: CD003 | L43: BẮN ỐC VÍT | M43: 2 | N43: 0.75 | O43: M000 | P43: 8 | Q43: 0 | R43: 0 | S43: 14 | T43: =M43*73 -> 146 | U43: =T43*N43/60 -> 1.825
G44: BTP1850000000CC | H44: =VLOOKUP(G44, 'DM_định mức sản phẩm'!C:D, 2, 0) -> Chân WNL (580*550*30) - Bàn 1 | I44: =_xlfn.XLOOKUP(K44, 'DM_công đoạn'!$H$3:$H$1000, 'DM_công đoạn'!$I$3:$I$1000) -> BP003 | J44: =_xlfn.XLOOKUP(L44, 'DM_công đoạn'!$B$3:$B$1000, 'DM_công đoạn'!$C$3:$C$1000) -> GIA CÔNG NEWLD | K44: CD010 | L44: CẮT | M44: 2 | N44: 0.73333333 | O44: M002 | P44: 1 | Q44: 1 | R44: 2 | S44: 7 | T44: =M44*73 -> 146 | U44: =T44*N44/60 -> 1.7844444
G45: BTP1850000000C3 | H45: =VLOOKUP(G45, 'DM_định mức sản phẩm'!C:D, 2, 0) -> Chân WNL (580*550*30) - Bàn 1 | I45: =_xlfn.XLOOKUP(K45, 'DM_công đoạn'!$H$3:$H$1000, 'DM_công đoạn'!$I$3:$I$1000) -> BP003 | J45: =_xlfn.XLOOKUP(L45, 'DM_công đoạn'!$B$3:$B$1000, 'DM_công đoạn'!$C$3:$C$1000) -> GIA CÔNG NEWLD | K45: CD029 | L45: CNC | M45: 2 | N45: 5.8 | O45: M011, M012, M013 | P45: 3 | Q45: 1 | R45: 30 | S45: 8 | T45: =M45*73 -> 146 | U45: =T45*N45/60 -> 14.113333
G46: BTP1850000000KC | H46: =VLOOKUP(G46, 'DM_định mức sản phẩm'!C:D, 2, 0) -> Chân WNL (580*550*30) - Bàn 1 | I46: =_xlfn.XLOOKUP(K46, 'DM_công đoạn'!$H$3:$H$1000, 'DM_công đoạn'!$I$3:$I$1000) -> BP003 | J46: =_xlfn.XLOOKUP(L46, 'DM_công đoạn'!$B$3:$B$1000, 'DM_công đoạn'!$C$3:$C$1000) -> GIA CÔNG NEWLD | K46: CD048 | L46: KHOAN | M46: 2 | N46: 0.5 | O46: M014, M015, M016, M017 | P46: 4 | Q46: 1 | R46: 20 | S46: 9 | T46: =M46*73 -> 146 | U46: =T46*N46/60 -> 1.2166667
G47: BTP1850000000N1 | H47: =VLOOKUP(G47, 'DM_định mức sản phẩm'!C:D, 2, 0) -> Chân WNL (580*550*30) - Bàn 1 | I47: =_xlfn.XLOOKUP(K47, 'DM_công đoạn'!$H$3:$H$1000, 'DM_công đoạn'!$I$3:$I$1000) -> BP007 | J47: =_xlfn.XLOOKUP(L47, 'DM_công đoạn'!$B$3:$B$1000, 'DM_công đoạn'!$C$3:$C$1000) -> CHÀ NHÁM | K47: CD026 | L47: CHÀ NHÁM 1 | M47: 2 | N47: 12.8 | O47: M000 | P47: 24 | Q47: 0 | R47: 0 | S47: 10 | T47: =M47*73 -> 146 | U47: =T47*N47/60 -> 31.146667
G48: BTP1850000000SL | H48: =VLOOKUP(G48, 'DM_định mức sản phẩm'!C:D, 2, 0) -> Chân WNL (580*550*30) - Bàn 1 | I48: =_xlfn.XLOOKUP(K48, 'DM_công đoạn'!$H$3:$H$1000, 'DM_công đoạn'!$I$3:$I$1000) -> BP008 | J48: =_xlfn.XLOOKUP(L48, 'DM_công đoạn'!$B$3:$B$1000, 'DM_công đoạn'!$C$3:$C$1000) -> SƠN | K48: CD075 | L48: SƠN LÓT | M48: 2 | N48: 0.8 | O48: M000 | P48: 12 | Q48: 0 | R48: 0 | S48: 11 | T48: =M48*73 -> 146 | U48: =T48*N48/60 -> 1.9466667
G49: BTP1850000000N2 | H49: =VLOOKUP(G49, 'DM_định mức sản phẩm'!C:D, 2, 0) -> Chân WNL (580*550*30) - Bàn 1 | I49: =_xlfn.XLOOKUP(K49, 'DM_công đoạn'!$H$3:$H$1000, 'DM_công đoạn'!$I$3:$I$1000) -> BP007 | J49: =_xlfn.XLOOKUP(L49, 'DM_công đoạn'!$B$3:$B$1000, 'DM_công đoạn'!$C$3:$C$1000) -> CHÀ NHÁM | K49: CD027 | L49: CHÀ NHÁM 2 | M49: 2 | N49: 5 | O49: M000 | P49: 24 | Q49: 0 | R49: 0 | S49: 12 | T49: =M49*73 -> 146 | U49: =T49*N49/60 -> 12.166667
... G69: BTP2010000000C2 | H69: =VLOOKUP(G69, 'DM_định mức sản phẩm'!C:D, 2, 0) -> Ván tầng WNL (898*200*15.5) - Bàn 2 | I69: =_xlfn.XLOOKUP(K69, 'DM_công đoạn'!$H$3:$H$1000, 'DM_công đoạn'!$I$3:$I$1000) -> BP003 | J69: =_xlfn.XLOOKUP(L69, 'DM_công đoạn'!$B$3:$B$1000, 'DM_công đoạn'!$C$3:$C$1000) -> GIA CÔNG NEWLD | K69: CD029 | L69: CNC | M69: 1 | N69: 1.5 | O69: M011, M012, M013 | P69: 3 | Q69: 1 | R69: 30 | S69: 32 | T69: =M69*73 -> 73 | U69: =T69*N69/60 -> 1.825
G70: 4550182598506 | H70: =VLOOKUP(G70, 'DM_định mức sản phẩm'!C:D, 2, 0) -> Table 2 - wnl | I70: =_xlfn.XLOOKUP(K70, 'DM_công đoạn'!$H$3:$H$1000, 'DM_công đoạn'!$I$3:$I$1000) -> BP001 | J70: =_xlfn.XLOOKUP(L70, 'DM_công đoạn'!$B$3:$B$1000, 'DM_công đoạn'!$C$3:$C$1000) -> LẮP RÁP ĐÓNG GÓI | K70: CD038 | L70: ĐÓNG GÓI | M70: 1 | N70: 3.3333333 | O70: M000 | P70: 8 | Q70: 0 | R70: 0 | S70: 33 | T70: 73 | U70: =T70*N70/60 -> 4.0555556
C71: 2023024Z2800 | E71: 55 | F71: 46143 | U71: =T71*N71/60 -> 0
C72: 4550182598513 | E72: 10 | F72: 46143 | U72: =T72*N72/60 -> 0
A73: 2 | B73: DHSX/12/2025/012 | C73: 4550182598476 | E73: 89
C74: 4550182598520 | E74: 76
C75: 2023024Z2800 | E75: 77
C76: 2023024Z2900 | E76: 100
A77: 3 | B77: DHSX/12/2025/013 | C77: 4550182598513 | E77: 87
C78: 4550182598476 | E78: 22
C79: 2023024Z2800 | E79: 66
...

Sheet Trang_tính3

Sheet Trang_tính2
